+ [author](https://github.com/3293172751)
+ <a href="https://github.com/3293172751" target="_blank"><img src="https://img.shields.io/badge/Github-xiongxinwei-inactive?style=social&logo=github"></a></p>

# 第16节 异常

+ [回到目录](../README.md)
+ [回到项目首页](../../README.md)
+ [上一节](15.md)
> ❤️💕💕java的学习指南,从入门到大师篇章。Myblog:[http://nsddd.top](http://nsddd.top/)
---
[TOC]

## Java 异常

在执行 Java 代码时，可能会出现不同的错误：程序员编写的编码错误、错误输入导致的错误或其他无法预料的事情。

发生错误时，Java 通常会停止并生成错误消息。对此的技术术语是：Java 将抛出**异常**（抛出错误）。

## Java 尝试和捕捉

该`try`语句允许您定义一个代码块，以便在执行时对其进行错误测试。

`catch`如果 try 块中发生错误，该语句允许您定义要执行的代码块。

和关键字成对出现`try`：`catch`

### 句法

```java
try {
  //  Block of code to try代码块尝试
}
catch(Exception e) {
  //  Block of code to handle errors 处理错误代码块
}
```

> 考虑以下示例：
>
> 这将产生错误，因为**myNumbers[10]**不存在。
>
> ```java
> public class Main {
>   public static void main(String[ ] args) {
>         int[] myNumbers = {1, 2, 3};
>         System.out.println(myNumbers[10]); // error!
>   	}
> }
> ```
>
> 输出将是这样的：
>
> ```
> Exception in thread "main" java.lang.ArrayIndexOutOfBoundsException: 10    at Main.main(Main.java:4)
> ```

如果发生错误，我们可以使用`try...catch`捕获错误并执行一些代码来处理它：

```java
public class Main {
  public static void main(String[ ] args) {
    try {
      int[] myNumbers = {1, 2, 3};
      System.out.println(myNumbers[10]);  //错误就不会输出
    } catch (Exception e) {
      System.out.println("Something went wrong.");
    }
  }
}
```

输出将是：

```
Something went wrong.
```

> 当然，如果程序是正确的依旧会返回
>
> ```java
> public class Main {
>   public static void main(String[] args) {
>     try {
>       int[] myNumbers = {1, 2, 3};
>       System.out.println(myNumbers[1]);
>     } catch (Exception e) {
>       System.out.println("Something went wrong.");
>     }
>   }
> }
> ```
>
> 最后的结果是：2



## 最后

该`finally`语句允许您在之后执行代码，`try...catch`而不管结果如何：

```java
public class Main {
  public static void main(String[] args) {
    try {
      int[] myNumbers = {1, 2, 3};
      System.out.println(myNumbers[10]);
    } catch (Exception e) {
      System.out.println("Something went wrong.");
    } finally {
      System.out.println("The 'try catch' is finished.");
    }
  }
}
 
```

输出将是：

```
Something went wrong.The 'try catch' is finished.
```



## throw 关键字

**该`throw`语句允许您创建自定义错误。**

该`throw`语句与**异常类型**一起使用。Java 中有许多可用的异常类型：`ArithmeticException`、 `FileNotFoundException`、`ArrayIndexOutOfBoundsException`、`SecurityException`等：

**如果年龄**低于 18岁，则抛出异常（打印“访问被拒绝”）。如果年龄为 18 岁或以上，请打印“访问权限”：

```java
public class Main {
  static void checkAge(int age) { 
    if (age < 18) {
    	System.out.println("你的年龄大于十八");
      throw new ArithmeticException("年龄如果小于18的话就会甩出来"); 
    } else {
      System.out.println("大于十八的话你需要授予访问权限,你老了!"); 
    }
 } 
 
 public static void main(String[] args) { 
   checkAge(18);
   checkAge(15);
   checkAge(19);
 } 
}
```

输出将是：

```
Exception in thread "main" java.lang.ArithmeticException: 年龄如果小于18的话就会甩出来
	at Main.checkAge(Main.java:5)
	at Main.main(Main.java:13)
```

如果**年龄**为 20 岁，则**不会**出现异常：

```java
public class Main {
  static void checkAge(int age) { 
    if (age < 18) {
    	System.out.println("你的年龄大于十八");
      throw new ArithmeticException("年龄如果小于18的话就会甩出来"); 
    } else {
      System.out.println("大于十八的话你需要授予访问权限,你老了!"); 
    }
 } 
 
 public static void main(String[] args) { 
 	checkAge(20);
 } 
}
```

输出将是：

```
大于十八的话你需要授予访问权限,你老了!
```



## END 链接
+ [回到目录](../README.md)
+ [上一节](15.md)
+ [下一节](17.md)
---
+ [参与贡献❤️💕💕](https://github.com/3293172751/Block_Chain/blob/master/Git/git-contributor.md)